 * Running on http://0.0.0.0:5425/ (Press CTRL+C to quit)
[2016-12-01 21:55:58,356] ERROR in app: Exception on /recipes [POST]
Traceback (most recent call last):
  File "/opt/webservice/rezeptbuch/flask/lib/python3.5/site-packages/flask/app.py", line 1639, in full_dispatch_request
    rv = self.dispatch_request()
  File "/opt/webservice/rezeptbuch/flask/lib/python3.5/site-packages/flask/app.py", line 1625, in dispatch_request
    return self.view_functions[rule.endpoint](**req.view_args)
  File "/opt/webservice/rezeptbuch/flask/lib/python3.5/site-packages/flask_restful/__init__.py", line 477, in wrapper
    resp = resource(*args, **kwargs)
  File "/opt/webservice/rezeptbuch/flask/lib/python3.5/site-packages/flask_httpauth.py", line 93, in decorated
    return f(*args, **kwargs)
  File "/opt/webservice/rezeptbuch/flask/lib/python3.5/site-packages/flask/views.py", line 84, in view
    return self.dispatch_request(*args, **kwargs)
  File "/opt/webservice/rezeptbuch/flask/lib/python3.5/site-packages/flask_restful/__init__.py", line 587, in dispatch_request
    resp = meth(*args, **kwargs)
  File "./app.py", line 48, in post
    result = db.insertRecipe(args['titel'], args['kategorie'], args['zutaten'], args['beschreibung'])
  File "/opt/webservice/rezeptbuch/util.py", line 96, in insertRecipe
    return marshal(res, self__recipe_fields)
NameError: name 'self__recipe_fields' is not defined
100.65.72.79 - - [01/Dec/2016 21:55:58] "POST /recipes HTTP/1.1" 500 -
